<?xml version="1.0" ?>
<!-- =================================================================================== -->
<!-- |    This document was autogenerated by xacro from rx1.urdf.xacro                 | -->
<!-- |    EDITING THIS FILE BY HAND IS NOT RECOMMENDED                                 | -->
<!-- =================================================================================== -->
<robot name="rx1">
  <material name="red">
    <color rgba="1 0 0 1"/>
  </material>
  <material name="white">
    <color rgba="1 1 1 1"/>
  </material>
  <material name="blue">
    <color rgba="0 0 1 1"/>
  </material>
  <link name="base_link">
    <inertial>
      <mass value="10.0"/>
      <inertia ixx="0.1" ixy="0.0" ixz="0.0" iyy="0.04" iyz="0.0" izz="0.2"/>
      <!--inertia ixx="1" ixy="0.0" ixz="0.0" iyy="1" iyz="0.0" izz="1" /-->
    </inertial>
    <visual>
      <geometry>
        <!--box size="0.02 0.02 0.5" /-->
        <mesh filename="package://rx1_description/meshes/base_link.stl"/>
      </geometry>
      <material name="white"/>
    </visual>
    <collision>
      <geometry>
        <!--box size="0.02 0.02 0.5" /-->
        <mesh filename="package://rx1_description/meshes/base_link.stl"/>
      </geometry>
    </collision>
  </link>
  <!--
    <link name="camera_link">
        <inertial>
            <mass value="0.05" />
            <inertia ixx="4.16666667e-06" ixy="0.0" ixz="0.0" iyy="6.6666666667e-6" iyz="0.0" izz="04.16666667e-06" />
        </inertial>
        <visual>
            <geometry>
                <box size="0.02 0.08 0.02" />
            </geometry>
            <origin rpy="0 0 0" xyz="0 0 0"/>
            <material name="white"/>
        </visual>
        <collision>
            <geometry>
                <box size="0.03 0.12 0.02" />
            </geometry>
            <origin rpy="0 0 0" xyz="0 0 0"/>
        </collision>
    </link>
    <joint name="base2camera_joint" type="fixed">
        <origin xyz="0 0 0.40" rpy="0 0.5 0" />
        <parent link="base_link" />
        <child link="camera_link" />
    </joint>

    <link name="camera_color_optical_frame">
        <visual>
            <geometry>
                <box size="0.01 0.01 0.01" />
            </geometry>
            <origin rpy="0 0 0" xyz="0 0 0"/>
            <material name="white"/>
        </visual>
    </link>
    <joint name="camera2camera_joint" type="fixed">
        <origin xyz="0 0 0" rpy="-1.57 0 -1.57" />
        <parent link="camera_link" />
        <child link="camera_color_optical_frame" />
    </joint>
-->
  <!--                            TORSO START                         -->
  <link name="torso_yaw_link">
    <visual>
      <geometry>
        <mesh filename="package://rx1_description/meshes/torso_yaw_link.stl"/>
      </geometry>
      <origin rpy="0 0 0" xyz="0 0 0"/>
      <material name="white"/>
    </visual>
    <collision>
      <geometry>
        <mesh filename="package://rx1_description/meshes/torso_yaw_link.stl"/>
      </geometry>
      <origin rpy="0 0 0" xyz="0 0 0"/>
    </collision>
  </link>
  <joint name="base2torso_yaw_joint" type="revolute">
    <axis xyz="0 0 1"/>
    <limit effort="50.0" lower="-1.57075" upper="1.57075" velocity="15"/>
    <origin rpy="0 0 0" xyz="0 0 0.5825"/>
    <parent link="base_link"/>
    <child link="torso_yaw_link"/>
  </joint>
  <link name="torso_pitch_link">
    <visual>
      <geometry>
        <cylinder length="0.03" radius="0.015"/>
      </geometry>
      <origin rpy="1.57075 0 0" xyz="0 0 0"/>
      <material name="blue"/>
    </visual>
    <collision>
      <geometry>
        <cylinder length="0.03" radius="0.01"/>
      </geometry>
      <origin rpy="1.57075 0 0" xyz="0 0 0"/>
    </collision>
  </link>
  <joint name="torso_yaw2pitch_joint" type="revolute">
    <axis xyz="0 1 0"/>
    <limit effort="50.0" lower="-0.785375" upper="0.785375" velocity="15"/>
    <origin rpy="0 0 0" xyz="0 0 0.15"/>
    <parent link="torso_yaw_link"/>
    <child link="torso_pitch_link"/>
  </joint>
  <link name="torso_roll_link">
    <visual>
      <geometry>
        <cylinder length="0.03" radius="0.015"/>
      </geometry>
      <origin rpy="0 1.57075 0" xyz="0 0 0"/>
      <material name="red"/>
    </visual>
    <collision>
      <geometry>
        <cylinder length="0.03" radius="0.01"/>
      </geometry>
      <origin rpy="0 1.57075 0" xyz="0 0 0"/>
    </collision>
  </link>
  <joint name="torso_pitch2roll_joint" type="revolute">
    <axis xyz="1 0 0"/>
    <limit effort="50.0" lower="-0.785375" upper="0.785375" velocity="15"/>
    <origin rpy="0 0 0" xyz="0 0 0"/>
    <parent link="torso_pitch_link"/>
    <child link="torso_roll_link"/>
  </joint>
  <link name="torso_link">
    <inertial>
      <mass value="0.05"/>
      <inertia ixx="4.16666667e-06" ixy="0.0" ixz="0.0" iyy="6.6666666667e-6" iyz="0.0" izz="04.16666667e-06"/>
    </inertial>
    <visual>
      <geometry>
        <!--box size="0.03 0.12 0.02" /-->
        <mesh filename="package://rx1_description/meshes/torso_link.stl"/>
      </geometry>
      <origin rpy="0 0 0" xyz="0 0 0"/>
      <material name="white"/>
    </visual>
    <collision>
      <geometry>
        <!--box size="0.03 0.12 0.02" /-->
        <mesh filename="package://rx1_description/meshes/torso_link.stl"/>
      </geometry>
      <origin rpy="0 0 0" xyz="0 0 0"/>
    </collision>
  </link>
  <joint name="torso_roll2torso_joint" type="fixed">
    <origin rpy="0 0 0" xyz="0 0 0.08"/>
    <parent link="torso_roll_link"/>
    <child link="torso_link"/>
  </joint>
  <!--                            TORSO END                         -->
  <!--                            HEAD START                        -->
  <link name="head_base_link">
    <inertial>
      <mass value="0.05"/>
      <inertia ixx="4.16666667e-06" ixy="0.0" ixz="0.0" iyy="6.6666666667e-6" iyz="0.0" izz="04.16666667e-06"/>
    </inertial>
    <visual>
      <geometry>
        <mesh filename="package://rx1_description/meshes/head/head_base_link.stl"/>
      </geometry>
      <origin rpy="0 0 0" xyz="0 0 0"/>
      <material name="white"/>
    </visual>
    <collision>
      <geometry>
        <mesh filename="package://rx1_description/meshes/head/head_base_link.stl"/>
      </geometry>
      <origin rpy="0 0 0" xyz="0 0 0"/>
    </collision>
  </link>
  <joint name="torso2head_base_joint" type="fixed">
    <origin rpy="0 0 0" xyz="0 0 0.21"/>
    <parent link="torso_link"/>
    <child link="head_base_link"/>
  </joint>
  <link name="neck_yaw_link">
    <inertial>
      <mass value="0.05"/>
      <inertia ixx="4.16666667e-06" ixy="0.0" ixz="0.0" iyy="6.6666666667e-6" iyz="0.0" izz="04.16666667e-06"/>
    </inertial>
    <visual>
      <geometry>
        <mesh filename="package://rx1_description/meshes/head/neck_yaw_link.stl"/>
      </geometry>
      <origin rpy="0 0 0" xyz="0 0 0"/>
      <material name="white"/>
    </visual>
    <collision>
      <geometry>
        <mesh filename="package://rx1_description/meshes/head/neck_yaw_link.stl"/>
      </geometry>
      <origin rpy="0 0 0" xyz="0 0 0"/>
    </collision>
  </link>
  <joint name="head_base2neck_yaw_joint" type="revolute">
    <axis xyz="0 0 1"/>
    <limit effort="50.0" lower="-1.57075" upper="1.57075" velocity="15"/>
    <origin rpy="0 0 0" xyz="0 0 0"/>
    <parent link="head_base_link"/>
    <child link="neck_yaw_link"/>
  </joint>
  <link name="neck_pitch_link">
    <inertial>
      <mass value="0.05"/>
      <inertia ixx="4.16666667e-06" ixy="0.0" ixz="0.0" iyy="6.6666666667e-6" iyz="0.0" izz="04.16666667e-06"/>
    </inertial>
    <visual>
      <geometry>
        <mesh filename="package://rx1_description/meshes/head/neck_pitch_link.stl"/>
      </geometry>
      <origin rpy="0 0 0" xyz="0 0 0"/>
      <material name="white"/>
    </visual>
    <collision>
      <geometry>
        <mesh filename="package://rx1_description/meshes/head/neck_pitch_link.stl"/>
      </geometry>
      <origin rpy="0 0 0" xyz="0 0 0"/>
    </collision>
  </link>
  <joint name="neck_yaw2pitch_joint" type="revolute">
    <axis xyz="0 1 0"/>
    <limit effort="50.0" lower="-1.57075" upper="1.57075" velocity="15"/>
    <origin rpy="0 0 0" xyz="0 0 0.035"/>
    <parent link="neck_yaw_link"/>
    <child link="neck_pitch_link"/>
  </joint>
  <link name="head_depth_cam_mount_link">
    <inertial>
      <mass value="0.05"/>
      <inertia ixx="4.16666667e-06" ixy="0.0" ixz="0.0" iyy="6.6666666667e-6" iyz="0.0" izz="04.16666667e-06"/>
    </inertial>
    <visual>
      <geometry>
        <mesh filename="package://rx1_description/meshes/head/head_depth_cam_mount_link.stl"/>
      </geometry>
      <origin rpy="0 0 0" xyz="0 0 0"/>
      <material name="white"/>
    </visual>
    <collision>
      <geometry>
        <mesh filename="package://rx1_description/meshes/head/head_depth_cam_mount_link.stl"/>
      </geometry>
      <origin rpy="0 0 0" xyz="0 0 0"/>
    </collision>
  </link>
  <joint name="neck_pitch2head_depth_cam_mount_joint" type="revolute">
    <axis xyz="1 0 0"/>
    <limit effort="50.0" lower="-1.57075" upper="1.57075" velocity="15"/>
    <origin rpy="0 0 0" xyz="-0.01 0 0.1"/>
    <parent link="neck_pitch_link"/>
    <child link="head_depth_cam_mount_link"/>
  </joint>
  <link name="camera_link">
    <inertial>
      <mass value="0.05"/>
      <inertia ixx="4.16666667e-06" ixy="0.0" ixz="0.0" iyy="6.6666666667e-6" iyz="0.0" izz="04.16666667e-06"/>
    </inertial>
    <visual>
      <geometry>
        <box size="0.01 0.01 0.01"/>
      </geometry>
      <origin rpy="0 0 0" xyz="0 0 0"/>
      <material name="white"/>
    </visual>
    <collision>
      <geometry>
        <box size="0.01 0.01 0.01"/>
      </geometry>
      <origin rpy="0 0 0" xyz="0 0 0"/>
    </collision>
  </link>
  <joint name="head_depth_cam_mount2camera_joint" type="fixed">
    <origin rpy="0 0 0" xyz="0.05 0 0.03"/>
    <parent link="head_depth_cam_mount_link"/>
    <child link="camera_link"/>
  </joint>
  <link name="right_ear_link">
    <inertial>
      <mass value="0.05"/>
      <inertia ixx="4.16666667e-06" ixy="0.0" ixz="0.0" iyy="6.6666666667e-6" iyz="0.0" izz="04.16666667e-06"/>
    </inertial>
    <visual>
      <geometry>
        <mesh filename="package://rx1_description/meshes/head/right_ear_link.stl"/>
      </geometry>
      <origin rpy="0 0 0" xyz="0 0 0"/>
      <material name="white"/>
    </visual>
    <collision>
      <geometry>
        <mesh filename="package://rx1_description/meshes/head/right_ear_link.stl"/>
      </geometry>
      <origin rpy="0 0 0" xyz="0 0 0"/>
    </collision>
  </link>
  <joint name="head_depth_cam_mount2right_ear_joint" type="revolute">
    <axis xyz="0 1 0"/>
    <limit effort="50.0" lower="-1.57075" upper="1.57075" velocity="15"/>
    <origin rpy="0 0 0" xyz="0 -0.065 0.045"/>
    <parent link="head_depth_cam_mount_link"/>
    <child link="right_ear_link"/>
  </joint>
  <link name="left_ear_link">
    <inertial>
      <mass value="0.05"/>
      <inertia ixx="4.16666667e-06" ixy="0.0" ixz="0.0" iyy="6.6666666667e-6" iyz="0.0" izz="04.16666667e-06"/>
    </inertial>
    <visual>
      <geometry>
        <mesh filename="package://rx1_description/meshes/head/left_ear_link.stl"/>
      </geometry>
      <origin rpy="0 0 0" xyz="0 0 0"/>
      <material name="white"/>
    </visual>
    <collision>
      <geometry>
        <mesh filename="package://rx1_description/meshes/head/left_ear_link.stl"/>
      </geometry>
      <origin rpy="0 0 0" xyz="0 0 0"/>
    </collision>
  </link>
  <joint name="head_depth_cam_mount2left_ear_joint" type="revolute">
    <axis xyz="0 1 0"/>
    <limit effort="50.0" lower="-1.57075" upper="1.57075" velocity="15"/>
    <origin rpy="0 0 0" xyz="0 0.065 0.045"/>
    <parent link="head_depth_cam_mount_link"/>
    <child link="left_ear_link"/>
  </joint>
  <!--                            HEAD END                           -->
  <link name="right_shoul_base_link">
    <inertial>
      <mass value="0.05"/>
      <inertia ixx="4.16666667e-06" ixy="0.0" ixz="0.0" iyy="6.6666666667e-6" iyz="0.0" izz="04.16666667e-06"/>
    </inertial>
    <visual>
      <geometry>
        <cylinder length="0.075" radius="0.02"/>
      </geometry>
      <origin rpy="0 0 0" xyz="0 0 0.0375"/>
      <material name="white"/>
    </visual>
    <collision>
      <geometry>
        <cylinder length="0.075" radius="0.02"/>
      </geometry>
      <origin rpy="0 0 0" xyz="0 0 0.0375"/>
    </collision>
  </link>
  <joint name="head_base2right_shoul_base_joint" type="fixed">
    <origin rpy="1.04706195 0 0" xyz="0 -0.12 -0.05"/>
    <parent link="head_base_link"/>
    <child link="right_shoul_base_link"/>
  </joint>
  <link name="right_shoul_link">
    <visual>
      <geometry>
        <cylinder length="0.08" radius="0.03"/>
      </geometry>
      <origin rpy="0 0 0" xyz="0 0 0.04"/>
      <material name="red"/>
    </visual>
    <collision>
      <geometry>
        <cylinder length="0.08" radius="0.03"/>
      </geometry>
      <origin rpy="0 0 0" xyz="0 0 0.04"/>
    </collision>
  </link>
  <joint name="right_shoul_base2shoul_joint" type="revolute">
    <axis xyz="0 0 1"/>
    <limit effort="50.0" lower="-2.5132000000000003" upper="2.5132000000000003" velocity="15"/>
    <origin rpy="0 0 0" xyz="0 0 0.075"/>
    <parent link="right_shoul_base_link"/>
    <child link="right_shoul_link"/>
  </joint>
  <link name="right_shoul_rot_link">
    <visual>
      <geometry>
        <cylinder length="0.04" radius="0.03"/>
      </geometry>
      <origin rpy="0 1.57075 0" xyz="0 0 0"/>
      <material name="blue"/>
    </visual>
    <collision>
      <geometry>
        <cylinder length="0.04" radius="0.03"/>
      </geometry>
      <origin rpy="0 1.57075 0" xyz="0 0 0"/>
    </collision>
  </link>
  <joint name="right_shoul2shoul_rot_joint" type="revolute">
    <axis xyz="1 0 0"/>
    <limit effort="50.0" lower="-1.57075" upper="0.5026400000000001" velocity="15"/>
    <origin rpy="-1.04706195 0 0" xyz="0 0 0.08"/>
    <parent link="right_shoul_link"/>
    <child link="right_shoul_rot_link"/>
  </joint>
  <link name="right_upper_arm_link">
    <visual>
      <geometry>
        <!--cylinder length="0.085" radius="0.015" /-->
        <mesh filename="package://rx1_description/meshes/right_arm/right_upper_arm_link.stl"/>
      </geometry>
      <origin rpy="0 0 0" xyz="0 0 0"/>
      <material name="white"/>
    </visual>
    <collision>
      <geometry>
        <!--cylinder length="0.085" radius="0.015" /-->
        <mesh filename="package://rx1_description/meshes/right_arm/right_upper_arm_link.stl"/>
      </geometry>
      <origin rpy="0 0 0" xyz="0 0 0"/>
    </collision>
  </link>
  <joint name="right_shoul_rot2upper_arm_joint" type="fixed">
    <origin rpy="0 0 0" xyz="0 0 -0.0625"/>
    <parent link="right_shoul_rot_link"/>
    <child link="right_upper_arm_link"/>
  </joint>
  <link name="right_armrot_link">
    <visual>
      <geometry>
        <!--cylinder length="0.22" radius="0.03" /-->
        <mesh filename="package://rx1_description/meshes/right_arm/right_elbow_link.stl"/>
      </geometry>
      <origin rpy="0 0 0" xyz="0 0 -0.11"/>
      <material name="white"/>
    </visual>
    <collision>
      <geometry>
        <cylinder length="0.22" radius="0.03"/>
      </geometry>
      <origin rpy="0 0 0" xyz="0 0 -0.11"/>
    </collision>
  </link>
  <joint name="right_arm2armrot_joint" type="revolute">
    <axis xyz="0 0 1"/>
    <limit effort="50.0" lower="-1.57075" upper="1.57075" velocity="15"/>
    <origin rpy="0 0 0" xyz="0 0 -0.0625"/>
    <parent link="right_upper_arm_link"/>
    <child link="right_armrot_link"/>
  </joint>
  <link name="right_elbow_link">
    <visual>
      <geometry>
        <cylinder length="0.08" radius="0.03"/>
      </geometry>
      <origin rpy="0 1.57075 -1.57075" xyz="0 0 0"/>
      <material name="blue"/>
    </visual>
    <collision>
      <geometry>
        <cylinder length="0.08" radius="0.03"/>
      </geometry>
      <origin rpy="0 1.57075 -1.57075" xyz="0 0 0"/>
    </collision>
  </link>
  <joint name="right_armrot2elbow_joint" type="revolute">
    <axis xyz="0 1 0"/>
    <limit effort="50.0" lower="-2.19905" upper="0" velocity="15"/>
    <origin rpy="0 0 0" xyz="0 0 -0.22"/>
    <parent link="right_armrot_link"/>
    <child link="right_elbow_link"/>
  </joint>
  <link name="right_forearm_link">
    <visual>
      <geometry>
        <cylinder length="0.09" radius="0.03"/>
      </geometry>
      <origin rpy="0 0 0" xyz="0 0 0"/>
      <material name="white"/>
    </visual>
    <collision>
      <geometry>
        <cylinder length="0.09" radius="0.03"/>
      </geometry>
      <origin rpy="0 0 0" xyz="0 0 0"/>
    </collision>
  </link>
  <joint name="right_elbow2forearm_joint" type="fixed">
    <origin rpy="0 0 0" xyz="0 0 -0.045"/>
    <parent link="right_elbow_link"/>
    <child link="right_forearm_link"/>
  </joint>
  <link name="right_forearmrot_link">
    <visual>
      <geometry>
        <!--cylinder length="0.18" radius="0.015" /-->
        <mesh filename="package://rx1_description/meshes/right_arm/right_forearm_link.stl"/>
      </geometry>
      <origin rpy="0 0 0" xyz="0 0 -0.09"/>
      <material name="white"/>
    </visual>
    <collision>
      <geometry>
        <cylinder length="0.18" radius="0.015"/>
      </geometry>
      <origin rpy="0 0 0" xyz="0 0 -0.09"/>
    </collision>
  </link>
  <joint name="right_forearm2forearmrot_joint" type="revolute">
    <axis xyz="0 0 1"/>
    <limit effort="50.0" lower="-1.57075" upper="1.57075" velocity="15"/>
    <origin rpy="0 0 0" xyz="0 0 -0.045"/>
    <parent link="right_forearm_link"/>
    <child link="right_forearmrot_link"/>
  </joint>
  <link name="right_forearm_pitch_link">
    <visual>
      <geometry>
        <cylinder length="0.03" radius="0.015"/>
      </geometry>
      <origin rpy="1.57075 0 0" xyz="0 0 0"/>
      <material name="blue"/>
    </visual>
    <collision>
      <geometry>
        <cylinder length="0.03" radius="0.01"/>
      </geometry>
      <origin rpy="1.57075 0 0" xyz="0 0 0"/>
    </collision>
  </link>
  <joint name="right_forearmrot2forearm_pitch_joint" type="revolute">
    <axis xyz="0 1 0"/>
    <limit effort="50.0" lower="-0.785375" upper="0.785375" velocity="15"/>
    <origin rpy="0 0 0" xyz="0 0 -0.18"/>
    <parent link="right_forearmrot_link"/>
    <child link="right_forearm_pitch_link"/>
  </joint>
  <link name="right_forearm_roll_link">
    <visual>
      <geometry>
        <cylinder length="0.03" radius="0.015"/>
      </geometry>
      <origin rpy="0 1.57075 0" xyz="0 0 0"/>
      <material name="red"/>
    </visual>
    <collision>
      <geometry>
        <cylinder length="0.03" radius="0.01"/>
      </geometry>
      <origin rpy="0 1.57075 0" xyz="0 0 0"/>
    </collision>
  </link>
  <joint name="right_forearm_pitch2forearm_roll_joint" type="revolute">
    <axis xyz="1 0 0"/>
    <limit effort="50.0" lower="-0.785375" upper="0.785375" velocity="15"/>
    <origin rpy="0 0 0" xyz="0 0 0"/>
    <parent link="right_forearm_pitch_link"/>
    <child link="right_forearm_roll_link"/>
  </joint>
  <link name="right_hand_link">
    <visual>
      <geometry>
        <!--box size="0.04 0.02 0.12" /-->
        <mesh filename="package://rx1_description/meshes/right_arm/right_hand_link.stl"/>
      </geometry>
      <origin rpy="0 0 0" xyz="0 0 0"/>
      <material name="white"/>
    </visual>
    <collision>
      <geometry>
        <box size="0.04 0.02 0.12"/>
      </geometry>
      <origin rpy="0 0 0" xyz="0 0 0"/>
    </collision>
  </link>
  <joint name="right_forearm_roll2hand_joint" type="fixed">
    <origin rpy="0 0 0" xyz="0 0 -0.1"/>
    <parent link="right_forearm_roll_link"/>
    <child link="right_hand_link"/>
  </joint>
  <link name="left_shoul_base_link">
    <inertial>
      <mass value="0.05"/>
      <inertia ixx="4.16666667e-06" ixy="0.0" ixz="0.0" iyy="6.6666666667e-6" iyz="0.0" izz="04.16666667e-06"/>
    </inertial>
    <visual>
      <geometry>
        <cylinder length="0.075" radius="0.02"/>
      </geometry>
      <origin rpy="0 0 0" xyz="0 0 0.0375"/>
      <material name="white"/>
    </visual>
    <collision>
      <geometry>
        <cylinder length="0.075" radius="0.02"/>
      </geometry>
      <origin rpy="0 0 0" xyz="0 0 0.0375"/>
    </collision>
  </link>
  <joint name="head_base2left_shoul_base_joint" type="fixed">
    <origin rpy="-1.04706195 0 0" xyz="0 0.12 -0.05"/>
    <parent link="head_base_link"/>
    <child link="left_shoul_base_link"/>
  </joint>
  <link name="left_shoul_link">
    <visual>
      <geometry>
        <cylinder length="0.08" radius="0.03"/>
      </geometry>
      <origin rpy="0 0 0" xyz="0 0 0.04"/>
      <material name="red"/>
    </visual>
    <collision>
      <geometry>
        <cylinder length="0.08" radius="0.03"/>
      </geometry>
      <origin rpy="0 0 0" xyz="0 0 0.04"/>
    </collision>
  </link>
  <joint name="left_shoul_base2shoul_joint" type="revolute">
    <axis xyz="0 0 1"/>
    <limit effort="50.0" lower="-2.5132000000000003" upper="2.5132000000000003" velocity="15"/>
    <origin rpy="0 0 0" xyz="0 0 0.075"/>
    <parent link="left_shoul_base_link"/>
    <child link="left_shoul_link"/>
  </joint>
  <link name="left_shoul_rot_link">
    <visual>
      <geometry>
        <cylinder length="0.04" radius="0.03"/>
      </geometry>
      <origin rpy="0 1.57075 0" xyz="0 0 0"/>
      <material name="blue"/>
    </visual>
    <collision>
      <geometry>
        <cylinder length="0.04" radius="0.03"/>
      </geometry>
      <origin rpy="0 1.57075 0" xyz="0 0 0"/>
    </collision>
  </link>
  <joint name="left_shoul2shoul_rot_joint" type="revolute">
    <axis xyz="1 0 0"/>
    <limit effort="50.0" lower="-0.5026400000000001" upper="1.57075" velocity="15"/>
    <origin rpy="1.04706195 0 0" xyz="0 0 0.08"/>
    <parent link="left_shoul_link"/>
    <child link="left_shoul_rot_link"/>
  </joint>
  <link name="left_upper_arm_link">
    <visual>
      <geometry>
        <!--cylinder length="0.085" radius="0.015" /-->
        <mesh filename="package://rx1_description/meshes/left_arm/left_upper_arm_link.stl"/>
      </geometry>
      <origin rpy="0 0 0" xyz="0 0 0"/>
      <material name="white"/>
    </visual>
    <collision>
      <geometry>
        <!--cylinder length="0.085" radius="0.015" /-->
        <mesh filename="package://rx1_description/meshes/left_arm/left_upper_arm_link.stl"/>
      </geometry>
      <origin rpy="0 0 0" xyz="0 0 0"/>
    </collision>
  </link>
  <joint name="left_shoul_rot2upper_arm_joint" type="fixed">
    <origin rpy="0 0 0" xyz="0 0 -0.0625"/>
    <parent link="left_shoul_rot_link"/>
    <child link="left_upper_arm_link"/>
  </joint>
  <link name="left_armrot_link">
    <visual>
      <geometry>
        <!--cylinder length="0.22" radius="0.03" /-->
        <mesh filename="package://rx1_description/meshes/left_arm/left_elbow_link.stl"/>
      </geometry>
      <origin rpy="0 0 0" xyz="0 0 -0.11"/>
      <material name="white"/>
    </visual>
    <collision>
      <geometry>
        <cylinder length="0.22" radius="0.03"/>
      </geometry>
      <origin rpy="0 0 0" xyz="0 0 -0.11"/>
    </collision>
  </link>
  <joint name="left_arm2armrot_joint" type="revolute">
    <axis xyz="0 0 1"/>
    <limit effort="50.0" lower="-1.57075" upper="1.57075" velocity="15"/>
    <origin rpy="0 0 0" xyz="0 0 -0.0625"/>
    <parent link="left_upper_arm_link"/>
    <child link="left_armrot_link"/>
  </joint>
  <link name="left_elbow_link">
    <visual>
      <geometry>
        <cylinder length="0.08" radius="0.03"/>
      </geometry>
      <origin rpy="0 -1.57075 -1.57075" xyz="0 0 0"/>
      <material name="blue"/>
    </visual>
    <collision>
      <geometry>
        <cylinder length="0.08" radius="0.03"/>
      </geometry>
      <origin rpy="0 -1.57075 -1.57075" xyz="0 0 0"/>
    </collision>
  </link>
  <joint name="left_armrot2elbow_joint" type="revolute">
    <axis xyz="0 1 0"/>
    <limit effort="50.0" lower="-2.19905" upper="0" velocity="15"/>
    <origin rpy="0 0 0" xyz="0 0 -0.22"/>
    <parent link="left_armrot_link"/>
    <child link="left_elbow_link"/>
  </joint>
  <link name="left_forearm_link">
    <visual>
      <geometry>
        <cylinder length="0.09" radius="0.03"/>
      </geometry>
      <origin rpy="0 0 0" xyz="0 0 0"/>
      <material name="white"/>
    </visual>
    <collision>
      <geometry>
        <cylinder length="0.09" radius="0.03"/>
      </geometry>
      <origin rpy="0 0 0" xyz="0 0 0"/>
    </collision>
  </link>
  <joint name="left_elbow2forearm_joint" type="fixed">
    <origin rpy="0 0 0" xyz="0 0 -0.045"/>
    <parent link="left_elbow_link"/>
    <child link="left_forearm_link"/>
  </joint>
  <link name="left_forearmrot_link">
    <visual>
      <geometry>
        <!--cylinder length="0.18" radius="0.015" /-->
        <mesh filename="package://rx1_description/meshes/left_arm/left_forearm_link.stl"/>
      </geometry>
      <origin rpy="0 0 0" xyz="0 0 -0.09"/>
      <material name="white"/>
    </visual>
    <collision>
      <geometry>
        <cylinder length="0.18" radius="0.015"/>
      </geometry>
      <origin rpy="0 0 0" xyz="0 0 -0.09"/>
    </collision>
  </link>
  <joint name="left_forearm2forearmrot_joint" type="revolute">
    <axis xyz="0 0 1"/>
    <limit effort="50.0" lower="-1.57075" upper="1.57075" velocity="15"/>
    <origin rpy="0 0 0" xyz="0 0 -0.045"/>
    <parent link="left_forearm_link"/>
    <child link="left_forearmrot_link"/>
  </joint>
  <link name="left_forearm_pitch_link">
    <visual>
      <geometry>
        <cylinder length="0.03" radius="0.015"/>
      </geometry>
      <origin rpy="-1.57075 0 0" xyz="0 0 0"/>
      <material name="blue"/>
    </visual>
    <collision>
      <geometry>
        <cylinder length="0.03" radius="0.01"/>
      </geometry>
      <origin rpy="-1.57075 0 0" xyz="0 0 0"/>
    </collision>
  </link>
  <joint name="left_forearmrot2forearm_pitch_joint" type="revolute">
    <axis xyz="0 1 0"/>
    <limit effort="50.0" lower="-0.785375" upper="0.785375" velocity="15"/>
    <origin rpy="0 0 0" xyz="0 0 -0.18"/>
    <parent link="left_forearmrot_link"/>
    <child link="left_forearm_pitch_link"/>
  </joint>
  <link name="left_forearm_roll_link">
    <visual>
      <geometry>
        <cylinder length="0.03" radius="0.015"/>
      </geometry>
      <origin rpy="0 -1.57075 0" xyz="0 0 0"/>
      <material name="red"/>
    </visual>
    <collision>
      <geometry>
        <cylinder length="0.03" radius="0.01"/>
      </geometry>
      <origin rpy="0 -1.57075 0" xyz="0 0 0"/>
    </collision>
  </link>
  <joint name="left_forearm_pitch2forearm_roll_joint" type="revolute">
    <axis xyz="1 0 0"/>
    <limit effort="50.0" lower="-0.785375" upper="0.785375" velocity="15"/>
    <origin rpy="0 0 0" xyz="0 0 0"/>
    <parent link="left_forearm_pitch_link"/>
    <child link="left_forearm_roll_link"/>
  </joint>
  <link name="left_hand_link">
    <visual>
      <geometry>
        <!--box size="0.04 0.02 0.12" /-->
        <mesh filename="package://rx1_description/meshes/left_arm/left_hand_link.stl"/>
      </geometry>
      <origin rpy="0 0 0" xyz="0 0 0"/>
      <material name="white"/>
    </visual>
    <collision>
      <geometry>
        <box size="0.04 0.02 0.12"/>
      </geometry>
      <origin rpy="0 0 0" xyz="0 0 0"/>
    </collision>
  </link>
  <joint name="left_forearm_roll2hand_joint" type="fixed">
    <origin rpy="0 0 0" xyz="0 0 -0.1"/>
    <parent link="left_forearm_roll_link"/>
    <child link="left_hand_link"/>
  </joint>
  <!--                            ARM END                             -->
</robot>
