<?xml version="1.0"?>

<!--Note that the inertia values are placeholder and need to be updated for proper physics simulation-->

<robot name="rx1" xmlns:xacro="http://ros.org/wiki/xacro">
    <xacro:property name="pi" value="3.1415" />
    <xacro:property name="motor_torque" value="50.0"/>
    <xacro:property name="motor_vec" value="15"/>

    <material name="red">
        <color rgba="1 0 0 1"/>
    </material>

    <material name="white">
        <color rgba="1 1 1 1"/>
    </material>

    <material name="blue">
        <color rgba="0 0 1 1"/>
    </material>

    <xacro:macro name="default_inertial" params="mass">
        <inertial>
            <mass value="${mass}" />
            <inertia ixx="1.0" ixy="0.0" ixz="0.0" iyy="1.0" iyz="0.0" izz="1.0" />
        </inertial>
    </xacro:macro>

    <link name="base_link">
        <inertial>
            <mass value="10.0" />
            <inertia ixx="0.1" ixy="0.0" ixz="0.0" iyy="0.04" iyz="0.0" izz="0.2" />
        </inertial>

        <visual>
            <geometry>
                <mesh filename="package://rx1_description/meshes/base_link.stl"/>
            </geometry>
            <material name="white"/>
        </visual>
        <collision>
            <geometry>
                <mesh filename="package://rx1_description/meshes/base_link.stl"/>
            </geometry>
        </collision>
    </link>

    <!--                            TORSO START                         -->
    <link name="torso_yaw_link">
        <visual>
            <geometry>
                <mesh filename="package://rx1_description/meshes/torso_yaw_link.stl"/>
            </geometry>
            <origin rpy="0 0 0" xyz="0 0 0"/>
            <material name="white"/>
        </visual>
        <collision>
            <geometry>
                <mesh filename="package://rx1_description/meshes/torso_yaw_link.stl"/>
            </geometry>
            <origin rpy="0 0 0" xyz="0 0 0"/>
        </collision>
    </link>
    <joint name="base2torso_yaw_joint" type="revolute">
        <axis xyz="0 0 1" />
        <limit effort="${motor_torque}" lower="${-0.5*pi}" upper="${0.5*pi}" velocity="${motor_vec}"/>
        <origin xyz="0 0 0.5825" rpy="0 0 0" />
        <parent link="base_link" />
        <child link="torso_yaw_link" />
    </joint>

    <link name="torso_pitch_link">
        <visual>
            <geometry>
                <cylinder length="0.03" radius="0.015" />
            </geometry>
            <origin rpy="${0.5*pi} 0 0" xyz="0 0 0"/>
            <material name="blue"/>
        </visual>
        <collision>
            <geometry>
                <cylinder length="0.03" radius="0.01" />
            </geometry>
            <origin rpy="${0.5*pi} 0 0" xyz="0 0 0"/>
        </collision>
    </link>
    <joint name="torso_yaw2pitch_joint" type="revolute">
        <axis xyz="0 1 0" />
        <limit effort="${motor_torque}" lower="${-0.25*pi}" upper="${0.25*pi}" velocity="${motor_vec}"/>
        <origin xyz="0 0 0.15" rpy="0 0 0" />
        <parent link="torso_yaw_link" />
        <child link="torso_pitch_link" />
    </joint>

    <link name="torso_roll_link">
        <visual>
            <geometry>
                <cylinder length="0.03" radius="0.015" />
            </geometry>
            <origin rpy="0 ${0.5*pi} 0" xyz="0 0 0"/>
            <material name="red"/>
        </visual>
        <collision>
            <geometry>
                <cylinder length="0.03" radius="0.01" />
            </geometry>
            <origin rpy="0 ${0.5*pi} 0" xyz="0 0 0"/>
        </collision>
    </link>
    <joint name="torso_pitch2roll_joint" type="revolute">
        <axis xyz="1 0 0" />
        <limit effort="${motor_torque}" lower="${-0.25*pi}" upper="${0.25*pi}" velocity="${motor_vec}"/>
        <origin xyz="0 0 0" rpy="0 0 0" />
        <parent link="torso_pitch_link" />
        <child link="torso_roll_link" />
    </joint>
    
    <link name="torso_link">
        <inertial>
            <mass value="0.05" />
            <inertia ixx="4.16666667e-06" ixy="0.0" ixz="0.0" iyy="6.6666666667e-6" iyz="0.0" izz="04.16666667e-06" />
        </inertial>
        <visual>
            <geometry>
                <!--box size="0.03 0.12 0.02" /-->
                <mesh filename="package://rx1_description/meshes/torso_link.stl"/>
            </geometry>
            <origin rpy="0 0 0" xyz="0 0 0"/>
            <material name="white"/>
        </visual>
        <collision>
            <geometry>
                <!--box size="0.03 0.12 0.02" /-->
                <mesh filename="package://rx1_description/meshes/torso_link.stl"/>
            </geometry>
            <origin rpy="0 0 0" xyz="0 0 0"/>
        </collision>
    </link>
    <joint name="torso_roll2torso_joint" type="fixed">
        <origin xyz="0 0 0.08" rpy="0 0 0" />
        <parent link="torso_roll_link" />
        <child link="torso_link" />
    </joint>
    <!--                            TORSO END                         -->

    <!--                            HEAD START                        -->
    <link name="head_base_link">
        <inertial>
            <mass value="0.05" />
            <inertia ixx="4.16666667e-06" ixy="0.0" ixz="0.0" iyy="6.6666666667e-6" iyz="0.0" izz="04.16666667e-06" />
        </inertial>
        <visual>
            <geometry>
                <mesh filename="package://rx1_description/meshes/head/head_base_link.stl"/>
            </geometry>
            <origin rpy="0 0 0" xyz="0 0 0"/>
            <material name="white"/>
        </visual>
        <collision>
            <geometry>
                <mesh filename="package://rx1_description/meshes/head/head_base_link.stl"/>
            </geometry>
            <origin rpy="0 0 0" xyz="0 0 0"/>
        </collision>
    </link>
    <joint name="torso2head_base_joint" type="fixed">
        <origin xyz="0 0 0.21" rpy="0 0 0" />
        <parent link="torso_link" />
        <child link="head_base_link" />
    </joint>

    <link name="neck_yaw_link">
        <inertial>
            <mass value="0.05" />
            <inertia ixx="4.16666667e-06" ixy="0.0" ixz="0.0" iyy="6.6666666667e-6" iyz="0.0" izz="04.16666667e-06" />
        </inertial>
        <visual>
            <geometry>
                <mesh filename="package://rx1_description/meshes/head/neck_yaw_link.stl"/>
            </geometry>
            <origin rpy="0 0 0" xyz="0 0 0"/>
            <material name="white"/>
        </visual>
        <collision>
            <geometry>
                <mesh filename="package://rx1_description/meshes/head/neck_yaw_link.stl"/>
            </geometry>
            <origin rpy="0 0 0" xyz="0 0 0"/>
        </collision>
    </link>
    <joint name="head_base2neck_yaw_joint" type="revolute">
        <axis xyz="0 0 1" />
        <limit effort="${motor_torque}" lower="${-0.5*pi}" upper="${0.5*pi}" velocity="${motor_vec}"/>
        <origin xyz="0 0 0" rpy="0 0 0" />
        <parent link="head_base_link" />
        <child link="neck_yaw_link" />
    </joint>

    <link name="neck_pitch_link">
        <inertial>
            <mass value="0.05" />
            <inertia ixx="4.16666667e-06" ixy="0.0" ixz="0.0" iyy="6.6666666667e-6" iyz="0.0" izz="04.16666667e-06" />
        </inertial>
        <visual>
            <geometry>
                <mesh filename="package://rx1_description/meshes/head/neck_pitch_link.stl"/>
            </geometry>
            <origin rpy="0 0 0" xyz="0 0 0"/>
            <material name="white"/>
        </visual>
        <collision>
            <geometry>
                <mesh filename="package://rx1_description/meshes/head/neck_pitch_link.stl"/>
            </geometry>
            <origin rpy="0 0 0" xyz="0 0 0"/>
        </collision>
    </link>
    <joint name="neck_yaw2pitch_joint" type="revolute">
        <axis xyz="0 1 0" />
        <limit effort="${motor_torque}" lower="${-0.5*pi}" upper="${0.5*pi}" velocity="${motor_vec}"/>
        <origin xyz="0 0 0.035" rpy="0 0 0" />
        <parent link="neck_yaw_link" />
        <child link="neck_pitch_link" />
    </joint>

    <link name="head_depth_cam_mount_link">
        <inertial>
            <mass value="0.05" />
            <inertia ixx="4.16666667e-06" ixy="0.0" ixz="0.0" iyy="6.6666666667e-6" iyz="0.0" izz="04.16666667e-06" />
        </inertial>
        <visual>
            <geometry>
                <mesh filename="package://rx1_description/meshes/head/head_depth_cam_mount_link.stl"/>
            </geometry>
            <origin rpy="0 0 0" xyz="0 0 0"/>
            <material name="white"/>
        </visual>
        <collision>
            <geometry>
                <mesh filename="package://rx1_description/meshes/head/head_depth_cam_mount_link.stl"/>
            </geometry>
            <origin rpy="0 0 0" xyz="0 0 0"/>
        </collision>
    </link>
    <joint name="neck_pitch2head_depth_cam_mount_joint" type="revolute">
        <axis xyz="1 0 0" />
        <limit effort="${motor_torque}" lower="${-0.5*pi}" upper="${0.5*pi}" velocity="${motor_vec}"/>
        <origin xyz="-0.01 0 0.1" rpy="0 0 0" />
        <parent link="neck_pitch_link" />
        <child link="head_depth_cam_mount_link" />
    </joint>

    <link name="camera_link">
        <inertial>
            <mass value="0.05" />
            <inertia ixx="4.16666667e-06" ixy="0.0" ixz="0.0" iyy="6.6666666667e-6" iyz="0.0" izz="04.16666667e-06" />
        </inertial>
        <visual>
            <geometry>
                <box size="0.01 0.01 0.01" />
            </geometry>
            <origin rpy="0 0 0" xyz="0 0 0"/>
            <material name="white"/>
        </visual>
        <collision>
            <geometry>
                <box size="0.01 0.01 0.01" />
            </geometry>
            <origin rpy="0 0 0" xyz="0 0 0"/>
        </collision>
    </link>
    <joint name="head_depth_cam_mount2camera_joint" type="fixed">
        <origin xyz="0.05 0 0.03" rpy="0 0 0" />
        <parent link="head_depth_cam_mount_link" />
        <child link="camera_link" />
    </joint>

    <link name="right_ear_link">
        <inertial>
            <mass value="0.05" />
            <inertia ixx="4.16666667e-06" ixy="0.0" ixz="0.0" iyy="6.6666666667e-6" iyz="0.0" izz="04.16666667e-06" />
        </inertial>
        <visual>
            <geometry>
                <mesh filename="package://rx1_description/meshes/head/right_ear_link.stl"/>
            </geometry>
            <origin rpy="0 0 0" xyz="0 0 0"/>
            <material name="white"/>
        </visual>
        <collision>
            <geometry>
                <mesh filename="package://rx1_description/meshes/head/right_ear_link.stl"/>
            </geometry>
            <origin rpy="0 0 0" xyz="0 0 0"/>
        </collision>
    </link>
    <joint name="head_depth_cam_mount2right_ear_joint" type="revolute">
        <axis xyz="0 1 0" />
        <limit effort="${motor_torque}" lower="${-0.5*pi}" upper="${0.5*pi}" velocity="${motor_vec}"/>
        <origin xyz="0 -0.065 0.045" rpy="0 0 0" />
        <parent link="head_depth_cam_mount_link" />
        <child link="right_ear_link" />
    </joint>

    <link name="left_ear_link">
        <inertial>
            <mass value="0.05" />
            <inertia ixx="4.16666667e-06" ixy="0.0" ixz="0.0" iyy="6.6666666667e-6" iyz="0.0" izz="04.16666667e-06" />
        </inertial>
        <visual>
            <geometry>
                <mesh filename="package://rx1_description/meshes/head/left_ear_link.stl"/>
            </geometry>
            <origin rpy="0 0 0" xyz="0 0 0"/>
            <material name="white"/>
        </visual>
        <collision>
            <geometry>
                <mesh filename="package://rx1_description/meshes/head/left_ear_link.stl"/>
            </geometry>
            <origin rpy="0 0 0" xyz="0 0 0"/>
        </collision>
    </link>
    <joint name="head_depth_cam_mount2left_ear_joint" type="revolute">
        <axis xyz="0 1 0" />
        <limit effort="${motor_torque}" lower="${-0.5*pi}" upper="${0.5*pi}" velocity="${motor_vec}"/>
        <origin xyz="0 0.065 0.045" rpy="0 0 0" />
        <parent link="head_depth_cam_mount_link" />
        <child link="left_ear_link" />
    </joint>

    <!--                            HEAD END                           -->


    <!--                            ARM START                          -->
    <xacro:macro name="arm" params="prefix side">
        <link name="${prefix}_shoul_base_link">
            <inertial>
                <mass value="0.05" />
                <inertia ixx="4.16666667e-06" ixy="0.0" ixz="0.0" iyy="6.6666666667e-6" iyz="0.0" izz="04.16666667e-06" />
            </inertial>
           
            <visual>
                <geometry>
                    <cylinder length="0.075" radius="0.02" />
                </geometry>
                <origin rpy="0 0 0" xyz="0 0 0.0375"/>
                <material name="white"/>
            </visual>
            <collision>
                <geometry>
                    <cylinder length="0.075" radius="0.02" />
                </geometry>
                <origin rpy="0 0 0" xyz="0 0 0.0375"/>
            </collision>
        </link>
        <joint name="head_base2${prefix}_shoul_base_joint" type="fixed">
            <origin xyz="0 ${-0.12*side} -0.05" rpy="${0.3333*pi*side} 0 0" />
            <parent link="head_base_link" />
            <child link="${prefix}_shoul_base_link" />
        </joint>

        <link name="${prefix}_shoul_link">
            <visual>
                <geometry>
                    <cylinder length="0.08" radius="0.03" />
                </geometry>
                <origin rpy="0 0 0" xyz="0 0 0.04"/>
                <material name="red"/>
            </visual>
            <collision>
                <geometry>
                    <cylinder length="0.08" radius="0.03" />
                </geometry>
                <origin rpy="0 0 0" xyz="0 0 0.04"/>
            </collision>
        </link>
        <joint name="${prefix}_shoul_base2shoul_joint" type="revolute">
            <axis xyz="0 0 1" />
            <limit effort="${motor_torque}" lower="${-0.8*pi}" upper="${0.8*pi}" velocity="${motor_vec}"/>
            <origin xyz="0 0 0.075" rpy="0 0 0" />
            <parent link="${prefix}_shoul_base_link" />
            <child link="${prefix}_shoul_link" />
        </joint>

        <link name="${prefix}_shoul_rot_link">
            <visual>
                <geometry>
                    <cylinder length="0.04" radius="0.03" />
                </geometry>
                <origin rpy="0 ${0.5*pi} 0" xyz="0 0 0"/>
                <material name="blue"/>
            </visual>
            <collision>
                <geometry>
                    <cylinder length="0.04" radius="0.03" />
                </geometry>
                <origin rpy="0 ${0.5*pi} 0" xyz="0 0 0"/>
            </collision>
        </link>
        <joint name="${prefix}_shoul2shoul_rot_joint" type="revolute">
            <axis xyz="1 0 0" />
            <xacro:if value="${prefix == 'right'}">  
                <limit effort="${motor_torque}" lower="${-0.5*pi}" upper="${0.16*pi}" velocity="${motor_vec}"/>
            </xacro:if> 
            <xacro:if value="${prefix == 'left'}">  
                <limit effort="${motor_torque}" lower="${-0.16*pi}" upper="${0.5*pi}" velocity="${motor_vec}"/>
            </xacro:if> 
            <origin xyz="0 0 0.08" rpy="${-0.3333*pi*side} 0 0" />
            <parent link="${prefix}_shoul_link" />
            <child link="${prefix}_shoul_rot_link" />
        </joint>


        <link name="${prefix}_upper_arm_link">
            <visual>
                <geometry>
                    <!--cylinder length="0.085" radius="0.015" /-->
                    <mesh filename="package://rx1_description/meshes/${prefix}_arm/${prefix}_upper_arm_link.stl"/>
                </geometry>
                <origin rpy="0 0 0" xyz="0 0 0"/>
                <material name="white"/>
            </visual>
            <collision>
                <geometry>
                    <!--cylinder length="0.085" radius="0.015" /-->
                    <mesh filename="package://rx1_description/meshes/${prefix}_arm/${prefix}_upper_arm_link.stl"/>
                </geometry>
                <origin rpy="0 0 0" xyz="0 0 0"/>
            </collision>
        </link>
        <joint name="${prefix}_shoul_rot2upper_arm_joint" type="fixed">
            <origin xyz="0 0 -0.0625" rpy="0 0 0" />
            <parent link="${prefix}_shoul_rot_link" />
            <child link="${prefix}_upper_arm_link" />
        </joint>


        <link name="${prefix}_armrot_link">
            <visual>
                <geometry>
                    <!--cylinder length="0.22" radius="0.03" /-->
                    <mesh filename="package://rx1_description/meshes/${prefix}_arm/${prefix}_elbow_link.stl"/>
                </geometry>
                <origin rpy="0 0 0" xyz="0 0 -0.11"/>
                <material name="white"/>
            </visual>
            <collision>
                <geometry>
                    <cylinder length="0.22" radius="0.03" />
                </geometry>
                <origin rpy="0 0 0" xyz="0 0 -0.11"/>
            </collision>
        </link>
        <joint name="${prefix}_arm2armrot_joint" type="revolute">
            <axis xyz="0 0 1" />
            <limit effort="${motor_torque}" lower="${-0.5*pi}" upper="${0.5*pi}" velocity="${motor_vec}"/>
            <origin xyz="0 0 -0.0625" rpy="0 0 0" />
            <parent link="${prefix}_upper_arm_link" />
            <child link="${prefix}_armrot_link" />
        </joint>

        <link name="${prefix}_elbow_link">
            <visual>
                <geometry>
                    <cylinder length="0.08" radius="0.03" />
                </geometry>
                <origin rpy="0 ${0.5*pi*side} -${0.5*pi}" xyz="0 0 0"/>
                <material name="blue"/>
            </visual>
            <collision>
                <geometry>
                    <cylinder length="0.08" radius="0.03" />
                </geometry>
                <origin rpy="0 ${0.5*pi*side} -${0.5*pi}" xyz="0 0 0"/>
            </collision>
        </link>
        <joint name="${prefix}_armrot2elbow_joint" type="revolute">
            <axis xyz="0 1 0" />
            <limit effort="${motor_torque}" lower="${-0.7*pi}" upper="0" velocity="${motor_vec}"/>
            <origin xyz="0 0 -0.22" rpy="0 0 0" />
            <parent link="${prefix}_armrot_link" />
            <child link="${prefix}_elbow_link" />
        </joint>

        <link name="${prefix}_forearm_link">
            <visual>
                <geometry>
                    <cylinder length="0.09" radius="0.03" />
                </geometry>
                <origin rpy="0 0 0" xyz="0 0 0"/>
                <material name="white"/>
            </visual>
            <collision>
                <geometry>
                    <cylinder length="0.09" radius="0.03" />
                </geometry>
                <origin rpy="0 0 0" xyz="0 0 0"/>
            </collision>
        </link>
        <joint name="${prefix}_elbow2forearm_joint" type="fixed">
            <origin xyz="0 0 -0.045" rpy="0 0 0" />
            <parent link="${prefix}_elbow_link" />
            <child link="${prefix}_forearm_link" />
        </joint>

        <link name="${prefix}_forearmrot_link">
            <visual>
                <geometry>
                    <!--cylinder length="0.18" radius="0.015" /-->
                    <mesh filename="package://rx1_description/meshes/${prefix}_arm/${prefix}_forearm_link.stl"/>
                </geometry>
                <origin rpy="0 0 0" xyz="0 0 -0.09"/>
                <material name="white"/>
            </visual>
            <collision>
                <geometry>
                    <cylinder length="0.18" radius="0.015" />
                </geometry>
                <origin rpy="0 0 0" xyz="0 0 -0.09"/>
            </collision>
        </link>
        <joint name="${prefix}_forearm2forearmrot_joint" type="revolute">
            <axis xyz="0 0 1" />
            <limit effort="${motor_torque}" lower="${-0.5*pi}" upper="${0.5*pi}" velocity="${motor_vec}"/>
            <origin xyz="0 0 -0.045" rpy="0 0 0" />
            <parent link="${prefix}_forearm_link" />
            <child link="${prefix}_forearmrot_link" />
        </joint>

        <link name="${prefix}_forearm_pitch_link">
            <visual>
                <geometry>
                    <cylinder length="0.03" radius="0.015" />
                </geometry>
                <origin rpy="${0.5*pi*side} 0 0" xyz="0 0 0"/>
                <material name="blue"/>
            </visual>
            <collision>
                <geometry>
                    <cylinder length="0.03" radius="0.01" />
                </geometry>
                <origin rpy="${0.5*pi*side} 0 0" xyz="0 0 0"/>
            </collision>
        </link>
        <joint name="${prefix}_forearmrot2forearm_pitch_joint" type="revolute">
            <axis xyz="0 1 0" />
            <limit effort="${motor_torque}" lower="${-0.25*pi}" upper="${0.25*pi}" velocity="${motor_vec}"/>
            <origin xyz="0 0 -0.18" rpy="0 0 0" />
            <parent link="${prefix}_forearmrot_link" />
            <child link="${prefix}_forearm_pitch_link" />
        </joint>

        <link name="${prefix}_forearm_roll_link">
            <visual>
                <geometry>
                    <cylinder length="0.03" radius="0.015" />
                </geometry>
                <origin rpy="0 ${0.5*pi*side} 0" xyz="0 0 0"/>
                <material name="red"/>
            </visual>
            <collision>
                <geometry>
                    <cylinder length="0.03" radius="0.01" />
                </geometry>
                <origin rpy="0 ${0.5*pi*side} 0" xyz="0 0 0"/>
            </collision>
        </link>
        <joint name="${prefix}_forearm_pitch2forearm_roll_joint" type="revolute">
            <axis xyz="1 0 0" />
            <limit effort="${motor_torque}" lower="${-0.25*pi}" upper="${0.25*pi}" velocity="${motor_vec}"/>
            <origin xyz="0 0 0" rpy="0 0 0" />
            <parent link="${prefix}_forearm_pitch_link" />
            <child link="${prefix}_forearm_roll_link" />
        </joint>

        <link name="${prefix}_hand_link">
            <visual>
                <geometry>
                    <!--box size="0.04 0.02 0.12" /-->
                    <mesh filename="package://rx1_description/meshes/${prefix}_arm/${prefix}_hand_link.stl"/>
                </geometry>
                <origin rpy="0 0 0" xyz="0 0 0"/>
                <material name="white"/>
            </visual>
            <collision>
                <geometry>
                    <box size="0.04 0.02 0.12" />
                </geometry>
                <origin rpy="0 0 0" xyz="0 0 0"/>
            </collision>
        </link>
        <joint name="${prefix}_forearm_roll2hand_joint" type="fixed">
            <origin xyz="0 0 -0.1" rpy="0 0 0" />
            <parent link="${prefix}_forearm_roll_link" />
            <child link="${prefix}_hand_link" />
        </joint>
    
    </xacro:macro>

    <xacro:arm prefix="right" side="1" />
    <xacro:arm prefix="left" side="-1" />

    <!--                            ARM END                             -->

</robot>
